Workbook

Sheet VENTAS DIARIAS
B2: FECHAS | C2: TIPO DE INGRESO | D2: DETALLE | E2: MONTO | F2: Columna 1
B3: 46035 | C3: EFECTIVO | D3: IMPREGNADOS | E3: 170000
B4: 46035 | C4: TRANSFERENCIA | D4: PEDIDO | E4: 475000
B5: 46036 | C5: EFECTIVO | D5: IMPREGNADOS | E5: 400000
B6: 46038 | C6: TRANSFERENCIA | D6: SEÑA PEDIDO | E6: 500000
B7: 46038 | C7: TRANSFERENCIA | D7: PEDIDO | E7: 1197500
B8: 46038 | C8: EFECTIVO | D8: PEDIDO | E8: 1097500
B9: 46041 | C9: EFECTIVO | D9: 3X3 | E9: 93800
B10: 46042 | C10: TRANSFERENCIA | D10: PEDIDO | E10: 358700
B11: 46043 | C11: TRANSFERENCIA | D11: PEDIDO | E11: 1260000
B12: 46046 | C12: EFECTIVO | D12: IMPREGNADOS | E12: 108000
B13: 46046 | C13: TRANSFERENCIA | D13: FENOLICOS | E13: 168000
B14: 46046 | C14: TRANSFERENCIA | D14: ALAMO | E14: 39000
... B341: 46073 | C341: TRANSFERENCIA | D341: TERZI | E341: 522000
B342: 46073 | C342: TRANSFERENCIA | E342: 280000
B343: 46073 | C343: EFECTIVO | D343: PUNTALES | E343: 600000
B344: 46074 | C344: EFECTIVO | D344: PEDIDO | E344: 370000
B345: 46074 | C345: EFECTIVO | D345: PEDIDO | E345: 1718000
B346: 46074 | C346: TRANSFERENCIA | D346: MACHIMBRE | E346: 56000
B347: 46077 | C347: TRANSFERENCIA | D347: IMPREGNADOS | E347: 50000
B348: 46077 | C348: TRANSFERENCIA | D348: IMPREGNADOS | E348: 1080000
B349: 46078 | C349: TRANSFERENCIA | D349: SEÑA | E349: 160000
B350: 46078 | C350: TRANSFERENCIA | D350: ALFAJIA | E350: 64000
B351: 46078 | C351: TRANSFERENCIA | E351: 165000
B352: 46079 | C352: TRANSFERENCIA | D352: ALAMO | E352: 108000
B353: 46083 | C353: EFECTIVO | D353: ALAMO | E353: 40000
B354: 46083 | C354: TRANSFERENCIA | D354: ROLLIZOS | E354: 32000
B355: 46086 | C355: DOLARES | D355: PEDIDO | E355: 1000000
B356: 46087 | C356: TRANSFERENCIA | D356: PEDIDO | E356: 5850000
B357: 46091 | C357: TRANSFERENCIA | D357: TERZI | E357: 800000
B358: 46098 | C358: EFECTIVO | D358: PUNTALES | E358: 100000
B359: 46099 | C359: EFECTIVO | D359: ALAMO | E359: 52000
B360: 46099 | C360: TRANSFERENCIA | D360: ALAMO | E360: 480000
B361: 46100 | C361: TRANSFERENCIA | D361: FENOLICO | E361: 213000
B362: 46100 | C362: TRANSFERENCIA | D362: TERZI | E362: 500000
B363: 46111 | C363: EFECTIVO | D363: IMPREGNADOS | E363: 237600
... B402: 46189 | C402: EFECTIVO | D402: IMPREGNADOS | E402: 150000
B403: 46192 | D403: PEDIDO | E403: 1000000
B404: 46192 | C404: TRANSFERENCIA | D404: PEDIDO | E404: 768000
B405: 46192 | C405: TRANSFERENCIA | D405: PEDIDO | E405: 1035000
...

Sheet BALANCE
B1: OCTUBRE | E1: MADERAS VICTORIA
B3: Día | C3: Ventas | D3: Gastos | E3: Impuestos | F3: Sueldos | G3: Proveedores | H3: Total Ingresos | I3: Total Egresos | J3: Resultado Neto
B4: Lunes | H4: =C4 | I4: =D4+E4+F4+G4 | J4: =H4-I4
B5: Martes | H5: =C5 | I5: =D5+E5+F5+G5 | J5: =H5-I5 | L5: AGUINALDOS
B6: Miércoles | H6: =C6 | I6: =D6+E6+F6+G6 | J6: =H6-I6 | L6: MARCOS | N6: JUAN | P6: ROMAN | R6: FERNANDO
A7: 46296 | B7: Jueves | C7: =IF($A7="","",SUMIF('VENTAS DIARIAS'!$B$2:$B$5000,$A7,'VENTAS DIARIAS'!$E$2:$E$5000)) | H7: =C7 | I7: =D7+E7+F7+G7 | J7: =H7-I7 | L7: 200000 | N7: 200000 | P7: 100000 | R7: 70000
A8: 46297 | B8: Viernes | C8: =IF($A8="","",SUMIF('VENTAS DIARIAS'!$B$2:$B$5000,$A8,'VENTAS DIARIAS'!$E$2:$E$5000)) | F8: 500000 | H8: =C8 | I8: =D8+E8+F8+G8 | J8: =H8-I8
A9: 46298 | B9: Sábado | C9: =IF($A9="","",SUMIF('VENTAS DIARIAS'!$B$2:$B$5000,$A9,'VENTAS DIARIAS'!$E$2:$E$5000)) | H9: =C9 | I9: =D9+E9+F9+G9 | J9: =H9-I9
B10: Total Semanal | C10: =SUM(C4:C9) | D10: =SUM(D4:D9) | E10: =SUM(E4:E9) | F10: =SUM(F4:F9) | G10: =SUM(G4:G9) | H10: =SUM(H4:H9) | I10: =SUM(I4:I9) | J10: =SUM(J4:J9)
A11: 46300 | B11: Lunes | C11: =IF($A11="","",SUMIF('VENTAS DIARIAS'!$B$2:$B$5000,$A11,'VENTAS DIARIAS'!$E$2:$E$5000)) | H11: =C11 | I11: =D11+E11+F11+G11 | J11: =H11-I11
A12: 46301 | B12: Martes | C12: =IF($A12="","",SUMIF('VENTAS DIARIAS'!$B$2:$B$5000,$A12,'VENTAS DIARIAS'!$E$2:$E$5000)) | H12: =C12 | I12: =D12+E12+F12+G12 | J12: =H12-I12
A13: 46302 | B13: Miércoles | C13: =IF($A13="","",SUMIF('VENTAS DIARIAS'!$B$2:$B$5000,$A13,'VENTAS DIARIAS'!$E$2:$E$5000)) | H13: =C13 | I13: =D13+E13+F13+G13 | J13: =H13-I13
A14: 46303 | B14: Jueves | C14: =IF($A14="","",SUMIF('VENTAS DIARIAS'!$B$2:$B$5000,$A14,'VENTAS DIARIAS'!$E$2:$E$5000)) | H14: =C14 | I14: =D14+E14+F14+G14 | J14: =H14-I14
A15: 46304 | B15: Viernes | C15: =IF($A15="","",SUMIF('VENTAS DIARIAS'!$B$2:$B$5000,$A15,'VENTAS DIARIAS'!$E$2:$E$5000)) | F15: 500000 | H15: =C15 | I15: =D15+E15+F15+G15 | J15: =H15-I15
A16: 46305 | B16: Sábado | C16: =IF($A16="","",SUMIF('VENTAS DIARIAS'!$B$2:$B$5000,$A16,'VENTAS DIARIAS'!$E$2:$E$5000)) | H16: =C16 | I16: =D16+E16+F16+G16 | J16: =H16-I16
B17: Total Semanal | C17: =SUM(C11:C16) | D17: =SUM(D11:D16) | E17: =SUM(E11:E16) | F17: =SUM(F11:F16) | G17: =SUM(G11:G16) | H17: =SUM(H11:H16) | I17: =SUM(I11:I16) | J17: =SUM(J11:J16)
A18: 46307 | B18: Lunes | C18: =IF($A18="","",SUMIF('VENTAS DIARIAS'!$B$2:$B$5000,$A18,'VENTAS DIARIAS'!$E$2:$E$5000)) | H18: =C18 | I18: =D18+E18+F18+G18 | J18: =H18-I18
A19: 46308 | B19: Martes | C19: =IF($A19="","",SUMIF('VENTAS DIARIAS'!$B$2:$B$5000,$A19,'VENTAS DIARIAS'!$E$2:$E$5000)) | H19: =C19 | I19: =D19+E19+F19+G19 | J19: =H19-I19
A20: 46309 | B20: Miércoles | C20: =IF($A20="","",SUMIF('VENTAS DIARIAS'!$B$2:$B$5000,$A20,'VENTAS DIARIAS'!$E$2:$E$5000)) | H20: =C20 | I20: =D20+E20+F20+G20 | J20: =H20-I20
A21: 46310 | B21: Jueves | C21: =IF($A21="","",SUMIF('VENTAS DIARIAS'!$B$2:$B$5000,$A21,'VENTAS DIARIAS'!$E$2:$E$5000)) | H21: =C21 | I21: =D21+E21+F21+G21 | J21: =H21-I21
A22: 46311 | B22: Viernes | C22: =IF($A22="","",SUMIF('VENTAS DIARIAS'!$B$2:$B$5000,$A22,'VENTAS DIARIAS'!$E$2:$E$5000)) | F22: 500000 | H22: =C22 | I22: =D22+E22+F22+G22 | J22: =H22-I22
A23: 46312 | B23: Sábado | C23: =IF($A23="","",SUMIF('VENTAS DIARIAS'!$B$2:$B$5000,$A23,'VENTAS DIARIAS'!$E$2:$E$5000)) | H23: =C23 | I23: =D23+E23+F23+G23 | J23: =H23-I23
B24: Total Semanal | C24: =SUM(C18:C23) | D24: =SUM(D18:D23) | E24: =SUM(E18:E23) | F24: =SUM(F18:F23) | G24: =SUM(G18:G23) | H24: =SUM(H18:H23) | I24: =SUM(I18:I23) | J24: =SUM(J18:J23)
A25: 46314 | B25: Lunes | C25: =IF($A25="","",SUMIF('VENTAS DIARIAS'!$B$2:$B$5000,$A25,'VENTAS DIARIAS'!$E$2:$E$5000)) | H25: =C25 | I25: =D25+E25+F25+G25 | J25: =H25-I25
A26: 46315 | B26: Martes | C26: =IF($A26="","",SUMIF('VENTAS DIARIAS'!$B$2:$B$5000,$A26,'VENTAS DIARIAS'!$E$2:$E$5000)) | H26: =C26 | I26: =D26+E26+F26+G26 | J26: =H26-I26
A27: 46316 | B27: Miércoles | C27: =IF($A27="","",SUMIF('VENTAS DIARIAS'!$B$2:$B$5000,$A27,'VENTAS DIARIAS'!$E$2:$E$5000)) | H27: =C27 | I27: =D27+E27+F27+G27 | J27: =H27-I27
A28: 46317 | B28: Jueves | C28: =IF($A28="","",SUMIF('VENTAS DIARIAS'!$B$2:$B$5000,$A28,'VENTAS DIARIAS'!$E$2:$E$5000)) | H28: =C28 | I28: =D28+E28+F28+G28 | J28: =H28-I28
A29: 46318 | B29: Viernes | C29: =IF($A29="","",SUMIF('VENTAS DIARIAS'!$B$2:$B$5000,$A29,'VENTAS DIARIAS'!$E$2:$E$5000)) | F29: 500000 | H29: =C29 | I29: =D29+E29+F29+G29 | J29: =H29-I29
A30: 46319 | B30: Sábado | C30: =IF($A30="","",SUMIF('VENTAS DIARIAS'!$B$2:$B$5000,$A30,'VENTAS DIARIAS'!$E$2:$E$5000)) | H30: =C30 | I30: =D30+E30+F30+G30 | J30: =H30-I30
B31: Total Semanal | C31: =SUM(C25:C30) | D31: =SUM(D25:D30) | E31: =SUM(E25:E30) | F31: =SUM(F25:F30) | G31: =SUM(G25:G30) | H31: =SUM(H25:H30) | I31: =SUM(I25:I30) | J31: =SUM(J25:J30)
A32: 46321 | B32: Lunes | C32: =IF($A32="","",SUMIF('VENTAS DIARIAS'!$B$2:$B$5000,$A32,'VENTAS DIARIAS'!$E$2:$E$5000)) | H32: =C32 | I32: =D32+E32+F32+G32 | J32: =H32-I32
A33: 46322 | B33: Martes | C33: =IF($A33="","",SUMIF('VENTAS DIARIAS'!$B$2:$B$5000,$A33,'VENTAS DIARIAS'!$E$2:$E$5000)) | H33: =C33 | I33: =D33+E33+F33+G33 | J33: =H33-I33
A34: 46323 | B34: Miércoles | C34: =IF($A34="","",SUMIF('VENTAS DIARIAS'!$B$2:$B$5000,$A34,'VENTAS DIARIAS'!$E$2:$E$5000)) | H34: =C34 | I34: =D34+E34+F34+G34 | J34: =H34-I34
A35: 46324 | B35: Jueves | C35: =IF($A35="","",SUMIF('VENTAS DIARIAS'!$B$2:$B$5000,$A35,'VENTAS DIARIAS'!$E$2:$E$5000)) | H35: =C35 | I35: =D35+E35+F35+G35 | J35: =H35-I35
A36: 46325 | B36: viernes | C36: =IF($A36="","",SUMIF('VENTAS DIARIAS'!$B$2:$B$5000,$A36,'VENTAS DIARIAS'!$E$2:$E$5000)) | F36: 500000 | H36: =C36 | I36: =D36+E36+F36+G36 | J36: =H36-I36
A37: 46326 | B37: sábado | C37: =IF($A37="","",SUMIF('VENTAS DIARIAS'!$B$2:$B$5000,$A37,'VENTAS DIARIAS'!$E$2:$E$5000)) | H37: =C37 | I37: =D37+E37+F37+G37 | J37: =H37-I37
B38: Total Semanal | C38: =SUM(C32:C37) | D38: =SUM(D32:D37) | E38: =SUM(E32:E37) | F38: =SUM(F32:F37) | G38: =SUM(G32:G37) | H38: =SUM(H32:H37) | I38: =SUM(I32:I37) | J38: =SUM(J32:J37)
B39: Total Mensual | C39: =C10+C17+C24+C31+C38 | D39: =D10+D17+D24+D31+D38 | E39: =E10+E17+E24+E31+E38 | F39: =F10+F17+F24+F31+F38 | G39: =G10+G17+G24+G31+G38 | H39: =H10+H17+H24+H31+H38 | I39: =I10+I17+I24+I31+I38 | J39: =J10+J17+J24+J31+J38

Sheet TARJETAS
B3: MES | C3: Ingresos | D3: Gastos | E3: Total Ingresos | G3: Total Egresos | H3: Resultado Neto
E4: =C4 | G4: =D4 | H4: =E4-G4
E5: =C5 | G5: =D5 | H5: =E5-G5
E6: =C6 | G6: =D6 | H6: =E6-G6
E7: =C7 | G7: =D7 | H7: =E7-G7
E8: =C8 | G8: =D8 | H8: =E8-G8
E9: =C9 | G9: =D9 | H9: =E9-G9
E10: =C10 | G10: =D10 | H10: =E10-G10
E11: =C11 | G11: =D11 | H11: =E11-G11
E12: =C12 | G12: =D12 | H12: =E12-G12
E13: =C13 | H13: =H4+H5+H6+H7+H8+H9+H10+H11+H12
B16: BANCO
B17: FECHA | C17: Ingresos | D17: Gastos | E17: Total Ingresos | F17: E-cheq | G17: Descubierto | H17: Resultado Neto | I17: Proveedor
B18: 46316 | E18: =C18 | F18: 697950 | G18: 10000000 | H18: =E18-G18-F18
B19: 46322 | F19: 1473218 | H19: =E19-G19-F19 | I19: VEIZA
B20: 46326 | E20: =C20 | F20: 780087 | G20: =D20 | H20: =E20-G20-F20 | I20: TEFQUIM
B21: 46336 | E21: =C21 | F21: 1000000 | G21: =D21 | H21: =E21-G21-F21 | I21: ALAMO
B22: 46347 | E22: =C22 | F22: 697950 | G22: =D22 | H22: =E22-G22-F22 | I22: VEIZA
B23: 46347 | E23: =C23 | F23: 782628 | G23: =D23 | H23: =E23-G23-F23 | I23: TEFQUIM
B24: 46351 | E24: =C24 | F24: 1453000 | G24: =D24 | H24: =E24-G24-F24 | I24: ALAMO
B25: 46354 | F25: 1473218 | H25: =E25-G25-F25 | I25: VEIZA
B26: 46356 | F26: 780087 | H26: =E26-G26-F26 | I26: TEFQUIM
B27: 46366 | F27: 1000000 | H27: =E27-G27-F27 | I27: ALAMO
B28: 46377 | F28: 782628 | H28: =E28-G28-F28 | I28: TEFQUIM
B29: 46381 | F29: 1453000 | H29: =E29-G29-F29 | I29: ALAMO
B30: 46043 | F30: 782628 | H30: =E30-G30-F30 | I30: TEFQUIM
H31: =E31-G31-F31
H32: =E32-G32-F32
H33: =E33-G33-F33
B34: TOTAL | E34: =C34 | G34: =D34 | H34: =SUM(H18:H33)
