Workbook
Name kikt: #REF!
Name PRODUCTOS: #REF!

Sheet CLIENTES
C1: Nombre : | F1: Fecha: | G1: 46316 | J1: PRESUPUESTO
C2: Direccion: | G2: 2615410210
C3: Telefono: | G3: 2615860139
A7: CANTIDADES | C7: PRODUCTOS | E7: DIAMETRO / ESPESOR | G7: DETALLE | H7: LARGO REAL | J7: LARGO A PEDIR | L7: PRECIO X METRO/U | M7: PRECIO TOTAL
J8: =IF($C8="","",IFERROR(IF(VLOOKUP($C8,PRECIOS!$A$2:$E$88,4,FALSE)<>"SI","",IF($H8="","",IF(OR(NOT(ISNUMBER($H8)),$H8<=0,$H8>50),"REVISAR LARGO",ROUND(ROUNDUP($H8/PRECIOS!$H$1,0)*PRECIOS!$H$1,2)))),"")) | L8: =IF($C8="","",IFERROR(IF(VLOOKUP($C8,PRECIOS!$A$2:$E$88,3,FALSE)="","SIN PRECIO",VLOOKUP($C8,PRECIOS!$A$2:$E$88,3,FALSE)),"NO EN LISTA")) | M8: =IF(OR($C8="",NOT(ISNUMBER($L8))),"",IF(VLOOKUP($C8,PRECIOS!$A$2:$E$88,4,FALSE)="SI",IF(NOT(ISNUMBER($J8)),"",$A8*$J8*$L8),$A8*$L8))
J9: =IF($C9="","",IFERROR(IF(VLOOKUP($C9,PRECIOS!$A$2:$E$88,4,FALSE)<>"SI","",IF($H9="","",IF(OR(NOT(ISNUMBER($H9)),$H9<=0,$H9>50),"REVISAR LARGO",ROUND(ROUNDUP($H9/PRECIOS!$H$1,0)*PRECIOS!$H$1,2)))),"")) | L9: =IF($C9="","",IFERROR(IF(VLOOKUP($C9,PRECIOS!$A$2:$E$88,3,FALSE)="","SIN PRECIO",VLOOKUP($C9,PRECIOS!$A$2:$E$88,3,FALSE)),"NO EN LISTA")) | M9: =IF(OR($C9="",NOT(ISNUMBER($L9))),"",IF(VLOOKUP($C9,PRECIOS!$A$2:$E$88,4,FALSE)="SI",IF(NOT(ISNUMBER($J9)),"",$A9*$J9*$L9),$A9*$L9))
J10: =IF($C10="","",IFERROR(IF(VLOOKUP($C10,PRECIOS!$A$2:$E$88,4,FALSE)<>"SI","",IF($H10="","",IF(OR(NOT(ISNUMBER($H10)),$H10<=0,$H10>50),"REVISAR LARGO",ROUND(ROUNDUP($H10/PRECIOS!$H$1,0)*PRECIOS!$H$1,2)))),"")) | L10: =IF($C10="","",IFERROR(IF(VLOOKUP($C10,PRECIOS!$A$2:$E$88,3,FALSE)="","SIN PRECIO",VLOOKUP($C10,PRECIOS!$A$2:$E$88,3,FALSE)),"NO EN LISTA")) | M10: =IF(OR($C10="",NOT(ISNUMBER($L10))),"",IF(VLOOKUP($C10,PRECIOS!$A$2:$E$88,4,FALSE)="SI",IF(NOT(ISNUMBER($J10)),"",$A10*$J10*$L10),$A10*$L10))
J11: =IF($C11="","",IFERROR(IF(VLOOKUP($C11,PRECIOS!$A$2:$E$88,4,FALSE)<>"SI","",IF($H11="","",IF(OR(NOT(ISNUMBER($H11)),$H11<=0,$H11>50),"REVISAR LARGO",ROUND(ROUNDUP($H11/PRECIOS!$H$1,0)*PRECIOS!$H$1,2)))),"")) | L11: =IF($C11="","",IFERROR(IF(VLOOKUP($C11,PRECIOS!$A$2:$E$88,3,FALSE)="","SIN PRECIO",VLOOKUP($C11,PRECIOS!$A$2:$E$88,3,FALSE)),"NO EN LISTA")) | M11: =IF(OR($C11="",NOT(ISNUMBER($L11))),"",IF(VLOOKUP($C11,PRECIOS!$A$2:$E$88,4,FALSE)="SI",IF(NOT(ISNUMBER($J11)),"",$A11*$J11*$L11),$A11*$L11))
J12: =IF($C12="","",IFERROR(IF(VLOOKUP($C12,PRECIOS!$A$2:$E$88,4,FALSE)<>"SI","",IF($H12="","",IF(OR(NOT(ISNUMBER($H12)),$H12<=0,$H12>50),"REVISAR LARGO",ROUND(ROUNDUP($H12/PRECIOS!$H$1,0)*PRECIOS!$H$1,2)))),"")) | L12: =IF($C12="","",IFERROR(IF(VLOOKUP($C12,PRECIOS!$A$2:$E$88,3,FALSE)="","SIN PRECIO",VLOOKUP($C12,PRECIOS!$A$2:$E$88,3,FALSE)),"NO EN LISTA")) | M12: =IF(OR($C12="",NOT(ISNUMBER($L12))),"",IF(VLOOKUP($C12,PRECIOS!$A$2:$E$88,4,FALSE)="SI",IF(NOT(ISNUMBER($J12)),"",$A12*$J12*$L12),$A12*$L12))
J13: =IF($C13="","",IFERROR(IF(VLOOKUP($C13,PRECIOS!$A$2:$E$88,4,FALSE)<>"SI","",IF($H13="","",IF(OR(NOT(ISNUMBER($H13)),$H13<=0,$H13>50),"REVISAR LARGO",ROUND(ROUNDUP($H13/PRECIOS!$H$1,0)*PRECIOS!$H$1,2)))),"")) | L13: =IF($C13="","",IFERROR(IF(VLOOKUP($C13,PRECIOS!$A$2:$E$88,3,FALSE)="","SIN PRECIO",VLOOKUP($C13,PRECIOS!$A$2:$E$88,3,FALSE)),"NO EN LISTA")) | M13: =IF(OR($C13="",NOT(ISNUMBER($L13))),"",IF(VLOOKUP($C13,PRECIOS!$A$2:$E$88,4,FALSE)="SI",IF(NOT(ISNUMBER($J13)),"",$A13*$J13*$L13),$A13*$L13))
J14: =IF($C14="","",IFERROR(IF(VLOOKUP($C14,PRECIOS!$A$2:$E$88,4,FALSE)<>"SI","",IF($H14="","",IF(OR(NOT(ISNUMBER($H14)),$H14<=0,$H14>50),"REVISAR LARGO",ROUND(ROUNDUP($H14/PRECIOS!$H$1,0)*PRECIOS!$H$1,2)))),"")) | L14: =IF($C14="","",IFERROR(IF(VLOOKUP($C14,PRECIOS!$A$2:$E$88,3,FALSE)="","SIN PRECIO",VLOOKUP($C14,PRECIOS!$A$2:$E$88,3,FALSE)),"NO EN LISTA")) | M14: =IF(OR($C14="",NOT(ISNUMBER($L14))),"",IF(VLOOKUP($C14,PRECIOS!$A$2:$E$88,4,FALSE)="SI",IF(NOT(ISNUMBER($J14)),"",$A14*$J14*$L14),$A14*$L14))
J15: =IF($C15="","",IFERROR(IF(VLOOKUP($C15,PRECIOS!$A$2:$E$88,4,FALSE)<>"SI","",IF($H15="","",IF(OR(NOT(ISNUMBER($H15)),$H15<=0,$H15>50),"REVISAR LARGO",ROUND(ROUNDUP($H15/PRECIOS!$H$1,0)*PRECIOS!$H$1,2)))),"")) | L15: =IF($C15="","",IFERROR(IF(VLOOKUP($C15,PRECIOS!$A$2:$E$88,3,FALSE)="","SIN PRECIO",VLOOKUP($C15,PRECIOS!$A$2:$E$88,3,FALSE)),"NO EN LISTA")) | M15: =IF(OR($C15="",NOT(ISNUMBER($L15))),"",IF(VLOOKUP($C15,PRECIOS!$A$2:$E$88,4,FALSE)="SI",IF(NOT(ISNUMBER($J15)),"",$A15*$J15*$L15),$A15*$L15))
J16: =IF($C16="","",IFERROR(IF(VLOOKUP($C16,PRECIOS!$A$2:$E$88,4,FALSE)<>"SI","",IF($H16="","",IF(OR(NOT(ISNUMBER($H16)),$H16<=0,$H16>50),"REVISAR LARGO",ROUND(ROUNDUP($H16/PRECIOS!$H$1,0)*PRECIOS!$H$1,2)))),"")) | L16: =IF($C16="","",IFERROR(IF(VLOOKUP($C16,PRECIOS!$A$2:$E$88,3,FALSE)="","SIN PRECIO",VLOOKUP($C16,PRECIOS!$A$2:$E$88,3,FALSE)),"NO EN LISTA")) | M16: =IF(OR($C16="",NOT(ISNUMBER($L16))),"",IF(VLOOKUP($C16,PRECIOS!$A$2:$E$88,4,FALSE)="SI",IF(NOT(ISNUMBER($J16)),"",$A16*$J16*$L16),$A16*$L16))
J17: =IF($C17="","",IFERROR(IF(VLOOKUP($C17,PRECIOS!$A$2:$E$88,4,FALSE)<>"SI","",IF($H17="","",IF(OR(NOT(ISNUMBER($H17)),$H17<=0,$H17>50),"REVISAR LARGO",ROUND(ROUNDUP($H17/PRECIOS!$H$1,0)*PRECIOS!$H$1,2)))),"")) | L17: =IF($C17="","",IFERROR(IF(VLOOKUP($C17,PRECIOS!$A$2:$E$88,3,FALSE)="","SIN PRECIO",VLOOKUP($C17,PRECIOS!$A$2:$E$88,3,FALSE)),"NO EN LISTA")) | M17: =IF(OR($C17="",NOT(ISNUMBER($L17))),"",IF(VLOOKUP($C17,PRECIOS!$A$2:$E$88,4,FALSE)="SI",IF(NOT(ISNUMBER($J17)),"",$A17*$J17*$L17),$A17*$L17))
J18: =IF($C18="","",IFERROR(IF(VLOOKUP($C18,PRECIOS!$A$2:$E$88,4,FALSE)<>"SI","",IF($H18="","",IF(OR(NOT(ISNUMBER($H18)),$H18<=0,$H18>50),"REVISAR LARGO",ROUND(ROUNDUP($H18/PRECIOS!$H$1,0)*PRECIOS!$H$1,2)))),"")) | L18: =IF($C18="","",IFERROR(IF(VLOOKUP($C18,PRECIOS!$A$2:$E$88,3,FALSE)="","SIN PRECIO",VLOOKUP($C18,PRECIOS!$A$2:$E$88,3,FALSE)),"NO EN LISTA")) | M18: =IF(OR($C18="",NOT(ISNUMBER($L18))),"",IF(VLOOKUP($C18,PRECIOS!$A$2:$E$88,4,FALSE)="SI",IF(NOT(ISNUMBER($J18)),"",$A18*$J18*$L18),$A18*$L18))
J19: =IF($C19="","",IFERROR(IF(VLOOKUP($C19,PRECIOS!$A$2:$E$88,4,FALSE)<>"SI","",IF($H19="","",IF(OR(NOT(ISNUMBER($H19)),$H19<=0,$H19>50),"REVISAR LARGO",ROUND(ROUNDUP($H19/PRECIOS!$H$1,0)*PRECIOS!$H$1,2)))),"")) | L19: =IF($C19="","",IFERROR(IF(VLOOKUP($C19,PRECIOS!$A$2:$E$88,3,FALSE)="","SIN PRECIO",VLOOKUP($C19,PRECIOS!$A$2:$E$88,3,FALSE)),"NO EN LISTA")) | M19: =IF(OR($C19="",NOT(ISNUMBER($L19))),"",IF(VLOOKUP($C19,PRECIOS!$A$2:$E$88,4,FALSE)="SI",IF(NOT(ISNUMBER($J19)),"",$A19*$J19*$L19),$A19*$L19))
... J27: =IF($C27="","",IFERROR(IF(VLOOKUP($C27,PRECIOS!$A$2:$E$88,4,FALSE)<>"SI","",IF($H27="","",IF(OR(NOT(ISNUMBER($H27)),$H27<=0,$H27>50),"REVISAR LARGO",ROUND(ROUNDUP($H27/PRECIOS!$H$1,0)*PRECIOS!$H$1,2)))),"")) | L27: =IF($C27="","",IFERROR(IF(VLOOKUP($C27,PRECIOS!$A$2:$E$88,3,FALSE)="","SIN PRECIO",VLOOKUP($C27,PRECIOS!$A$2:$E$88,3,FALSE)),"NO EN LISTA")) | M27: =IF(OR($C27="",NOT(ISNUMBER($L27))),"",IF(VLOOKUP($C27,PRECIOS!$A$2:$E$88,4,FALSE)="SI",IF(NOT(ISNUMBER($J27)),"",$A27*$J27*$L27),$A27*$L27))
J28: =IF($C28="","",IFERROR(IF(VLOOKUP($C28,PRECIOS!$A$2:$E$88,4,FALSE)<>"SI","",IF($H28="","",IF(OR(NOT(ISNUMBER($H28)),$H28<=0,$H28>50),"REVISAR LARGO",ROUND(ROUNDUP($H28/PRECIOS!$H$1,0)*PRECIOS!$H$1,2)))),"")) | L28: =IF($C28="","",IFERROR(IF(VLOOKUP($C28,PRECIOS!$A$2:$E$88,3,FALSE)="","SIN PRECIO",VLOOKUP($C28,PRECIOS!$A$2:$E$88,3,FALSE)),"NO EN LISTA")) | M28: =IF(OR($C28="",NOT(ISNUMBER($L28))),"",IF(VLOOKUP($C28,PRECIOS!$A$2:$E$88,4,FALSE)="SI",IF(NOT(ISNUMBER($J28)),"",$A28*$J28*$L28),$A28*$L28)) | O28: |
J29: =IF($C29="","",IFERROR(IF(VLOOKUP($C29,PRECIOS!$A$2:$E$88,4,FALSE)<>"SI","",IF($H29="","",IF(OR(NOT(ISNUMBER($H29)),$H29<=0,$H29>50),"REVISAR LARGO",ROUND(ROUNDUP($H29/PRECIOS!$H$1,0)*PRECIOS!$H$1,2)))),"")) | L29: =IF($C29="","",IFERROR(IF(VLOOKUP($C29,PRECIOS!$A$2:$E$88,3,FALSE)="","SIN PRECIO",VLOOKUP($C29,PRECIOS!$A$2:$E$88,3,FALSE)),"NO EN LISTA")) | M29: =IF(OR($C29="",NOT(ISNUMBER($L29))),"",IF(VLOOKUP($C29,PRECIOS!$A$2:$E$88,4,FALSE)="SI",IF(NOT(ISNUMBER($J29)),"",$A29*$J29*$L29),$A29*$L29))
J30: =IF($C30="","",IFERROR(IF(VLOOKUP($C30,PRECIOS!$A$2:$E$88,4,FALSE)<>"SI","",IF($H30="","",IF(OR(NOT(ISNUMBER($H30)),$H30<=0,$H30>50),"REVISAR LARGO",ROUND(ROUNDUP($H30/PRECIOS!$H$1,0)*PRECIOS!$H$1,2)))),"")) | L30: =IF($C30="","",IFERROR(IF(VLOOKUP($C30,PRECIOS!$A$2:$E$88,3,FALSE)="","SIN PRECIO",VLOOKUP($C30,PRECIOS!$A$2:$E$88,3,FALSE)),"NO EN LISTA")) | M30: =IF(OR($C30="",NOT(ISNUMBER($L30))),"",IF(VLOOKUP($C30,PRECIOS!$A$2:$E$88,4,FALSE)="SI",IF(NOT(ISNUMBER($J30)),"",$A30*$J30*$L30),$A30*$L30))
J31: =IF($C31="","",IFERROR(IF(VLOOKUP($C31,PRECIOS!$A$2:$E$88,4,FALSE)<>"SI","",IF($H31="","",IF(OR(NOT(ISNUMBER($H31)),$H31<=0,$H31>50),"REVISAR LARGO",ROUND(ROUNDUP($H31/PRECIOS!$H$1,0)*PRECIOS!$H$1,2)))),"")) | L31: =IF($C31="","",IFERROR(IF(VLOOKUP($C31,PRECIOS!$A$2:$E$88,3,FALSE)="","SIN PRECIO",VLOOKUP($C31,PRECIOS!$A$2:$E$88,3,FALSE)),"NO EN LISTA")) | M31: =IF(OR($C31="",NOT(ISNUMBER($L31))),"",IF(VLOOKUP($C31,PRECIOS!$A$2:$E$88,4,FALSE)="SI",IF(NOT(ISNUMBER($J31)),"",$A31*$J31*$L31),$A31*$L31))
J32: =IF($C32="","",IFERROR(IF(VLOOKUP($C32,PRECIOS!$A$2:$E$88,4,FALSE)<>"SI","",IF($H32="","",IF(OR(NOT(ISNUMBER($H32)),$H32<=0,$H32>50),"REVISAR LARGO",ROUND(ROUNDUP($H32/PRECIOS!$H$1,0)*PRECIOS!$H$1,2)))),"")) | L32: =IF($C32="","",IFERROR(IF(VLOOKUP($C32,PRECIOS!$A$2:$E$88,3,FALSE)="","SIN PRECIO",VLOOKUP($C32,PRECIOS!$A$2:$E$88,3,FALSE)),"NO EN LISTA")) | M32: =IF(OR($C32="",NOT(ISNUMBER($L32))),"",IF(VLOOKUP($C32,PRECIOS!$A$2:$E$88,4,FALSE)="SI",IF(NOT(ISNUMBER($J32)),"",$A32*$J32*$L32),$A32*$L32))
J33: =IF($C33="","",IFERROR(IF(VLOOKUP($C33,PRECIOS!$A$2:$E$88,4,FALSE)<>"SI","",IF($H33="","",IF(OR(NOT(ISNUMBER($H33)),$H33<=0,$H33>50),"REVISAR LARGO",ROUND(ROUNDUP($H33/PRECIOS!$H$1,0)*PRECIOS!$H$1,2)))),"")) | L33: =IF($C33="","",IFERROR(IF(VLOOKUP($C33,PRECIOS!$A$2:$E$88,3,FALSE)="","SIN PRECIO",VLOOKUP($C33,PRECIOS!$A$2:$E$88,3,FALSE)),"NO EN LISTA")) | M33: =IF(OR($C33="",NOT(ISNUMBER($L33))),"",IF(VLOOKUP($C33,PRECIOS!$A$2:$E$88,4,FALSE)="SI",IF(NOT(ISNUMBER($J33)),"",$A33*$J33*$L33),$A33*$L33))
J34: =IF($C34="","",IFERROR(IF(VLOOKUP($C34,PRECIOS!$A$2:$E$88,4,FALSE)<>"SI","",IF($H34="","",IF(OR(NOT(ISNUMBER($H34)),$H34<=0,$H34>50),"REVISAR LARGO",ROUND(ROUNDUP($H34/PRECIOS!$H$1,0)*PRECIOS!$H$1,2)))),"")) | L34: =IF($C34="","",IFERROR(IF(VLOOKUP($C34,PRECIOS!$A$2:$E$88,3,FALSE)="","SIN PRECIO",VLOOKUP($C34,PRECIOS!$A$2:$E$88,3,FALSE)),"NO EN LISTA")) | M34: =IF(OR($C34="",NOT(ISNUMBER($L34))),"",IF(VLOOKUP($C34,PRECIOS!$A$2:$E$88,4,FALSE)="SI",IF(NOT(ISNUMBER($J34)),"",$A34*$J34*$L34),$A34*$L34))
J35: =IF($C35="","",IFERROR(IF(VLOOKUP($C35,PRECIOS!$A$2:$E$88,4,FALSE)<>"SI","",IF($H35="","",IF(OR(NOT(ISNUMBER($H35)),$H35<=0,$H35>50),"REVISAR LARGO",ROUND(ROUNDUP($H35/PRECIOS!$H$1,0)*PRECIOS!$H$1,2)))),"")) | L35: =IF($C35="","",IFERROR(IF(VLOOKUP($C35,PRECIOS!$A$2:$E$88,3,FALSE)="","SIN PRECIO",VLOOKUP($C35,PRECIOS!$A$2:$E$88,3,FALSE)),"NO EN LISTA")) | M35: =IF(OR($C35="",NOT(ISNUMBER($L35))),"",IF(VLOOKUP($C35,PRECIOS!$A$2:$E$88,4,FALSE)="SI",IF(NOT(ISNUMBER($J35)),"",$A35*$J35*$L35),$A35*$L35))
J36: =IF($C36="","",IFERROR(IF(VLOOKUP($C36,PRECIOS!$A$2:$E$88,4,FALSE)<>"SI","",IF($H36="","",IF(OR(NOT(ISNUMBER($H36)),$H36<=0,$H36>50),"REVISAR LARGO",ROUND(ROUNDUP($H36/PRECIOS!$H$1,0)*PRECIOS!$H$1,2)))),"")) | L36: =IF($C36="","",IFERROR(IF(VLOOKUP($C36,PRECIOS!$A$2:$E$88,3,FALSE)="","SIN PRECIO",VLOOKUP($C36,PRECIOS!$A$2:$E$88,3,FALSE)),"NO EN LISTA")) | M36: =IF(OR($C36="",NOT(ISNUMBER($L36))),"",IF(VLOOKUP($C36,PRECIOS!$A$2:$E$88,4,FALSE)="SI",IF(NOT(ISNUMBER($J36)),"",$A36*$J36*$L36),$A36*$L36))
J37: =IF($C37="","",IFERROR(IF(VLOOKUP($C37,PRECIOS!$A$2:$E$88,4,FALSE)<>"SI","",IF($H37="","",IF(OR(NOT(ISNUMBER($H37)),$H37<=0,$H37>50),"REVISAR LARGO",ROUND(ROUNDUP($H37/PRECIOS!$H$1,0)*PRECIOS!$H$1,2)))),"")) | L37: =IF($C37="","",IFERROR(IF(VLOOKUP($C37,PRECIOS!$A$2:$E$88,3,FALSE)="","SIN PRECIO",VLOOKUP($C37,PRECIOS!$A$2:$E$88,3,FALSE)),"NO EN LISTA")) | M37: =IF(OR($C37="",NOT(ISNUMBER($L37))),"",IF(VLOOKUP($C37,PRECIOS!$A$2:$E$88,4,FALSE)="SI",IF(NOT(ISNUMBER($J37)),"",$A37*$J37*$L37),$A37*$L37))
J38: =IF($C38="","",IFERROR(IF(VLOOKUP($C38,PRECIOS!$A$2:$E$88,4,FALSE)<>"SI","",IF($H38="","",IF(OR(NOT(ISNUMBER($H38)),$H38<=0,$H38>50),"REVISAR LARGO",ROUND(ROUNDUP($H38/PRECIOS!$H$1,0)*PRECIOS!$H$1,2)))),"")) | L38: =IF($C38="","",IFERROR(IF(VLOOKUP($C38,PRECIOS!$A$2:$E$88,3,FALSE)="","SIN PRECIO",VLOOKUP($C38,PRECIOS!$A$2:$E$88,3,FALSE)),"NO EN LISTA")) | M38: =IF(OR($C38="",NOT(ISNUMBER($L38))),"",IF(VLOOKUP($C38,PRECIOS!$A$2:$E$88,4,FALSE)="SI",IF(NOT(ISNUMBER($J38)),"",$A38*$J38*$L38),$A38*$L38))
J39: =IF($C39="","",IFERROR(IF(VLOOKUP($C39,PRECIOS!$A$2:$E$88,4,FALSE)<>"SI","",IF($H39="","",IF(OR(NOT(ISNUMBER($H39)),$H39<=0,$H39>50),"REVISAR LARGO",ROUND(ROUNDUP($H39/PRECIOS!$H$1,0)*PRECIOS!$H$1,2)))),"")) | L39: =IF($C39="","",IFERROR(IF(VLOOKUP($C39,PRECIOS!$A$2:$E$88,3,FALSE)="","SIN PRECIO",VLOOKUP($C39,PRECIOS!$A$2:$E$88,3,FALSE)),"NO EN LISTA")) | M39: =IF(OR($C39="",NOT(ISNUMBER($L39))),"",IF(VLOOKUP($C39,PRECIOS!$A$2:$E$88,4,FALSE)="SI",IF(NOT(ISNUMBER($J39)),"",$A39*$J39*$L39),$A39*$L39))
J40: =IF($C40="","",IFERROR(IF(VLOOKUP($C40,PRECIOS!$A$2:$E$88,4,FALSE)<>"SI","",IF($H40="","",IF(OR(NOT(ISNUMBER($H40)),$H40<=0,$H40>50),"REVISAR LARGO",ROUND(ROUNDUP($H40/PRECIOS!$H$1,0)*PRECIOS!$H$1,2)))),"")) | L40: =IF($C40="","",IFERROR(IF(VLOOKUP($C40,PRECIOS!$A$2:$E$88,3,FALSE)="","SIN PRECIO",VLOOKUP($C40,PRECIOS!$A$2:$E$88,3,FALSE)),"NO EN LISTA")) | M40: =IF(OR($C40="",NOT(ISNUMBER($L40))),"",IF(VLOOKUP($C40,PRECIOS!$A$2:$E$88,4,FALSE)="SI",IF(NOT(ISNUMBER($J40)),"",$A40*$J40*$L40),$A40*$L40))
... J85: =IF($C85="","",IFERROR(IF(VLOOKUP($C85,PRECIOS!$A$2:$E$88,4,FALSE)<>"SI","",IF($H85="","",IF(OR(NOT(ISNUMBER($H85)),$H85<=0,$H85>50),"REVISAR LARGO",ROUND(ROUNDUP($H85/PRECIOS!$H$1,0)*PRECIOS!$H$1,2)))),"")) | L85: =IF($C85="","",IFERROR(IF(VLOOKUP($C85,PRECIOS!$A$2:$E$88,3,FALSE)="","SIN PRECIO",VLOOKUP($C85,PRECIOS!$A$2:$E$88,3,FALSE)),"NO EN LISTA")) | M85: =IF(OR($C85="",NOT(ISNUMBER($L85))),"",IF(VLOOKUP($C85,PRECIOS!$A$2:$E$88,4,FALSE)="SI",IF(NOT(ISNUMBER($J85)),"",$A85*$J85*$L85),$A85*$L85))
A86: PRECIOS MAS IVA | C86: TOTAL | H86: TOTAL | L86: =SUM(M8:M85)

Sheet PRECIOS
A1: PRODUCTO | B1: UNIDAD | C1: PRECIO | D1: MULTIPLICA LARGO | E1: PRECIO OK | G1: PASO DE CORTE (m) | H1: 0.5
A2: ROLLIZO 13-15CM | B2: METRO LINEAL | C2: 5000 | D2: SI | E2: =IF($C2="","SIN PRECIO",$C2)
A3: POSTE 16-18CM | B3: METRO LINEAL | C3: 6500 | D3: SI | E3: =IF($C3="","SIN PRECIO",$C3)
A4: VIGA 20-22 CM | B4: METRO LINEAL | C4: 7500 | D4: SI | E4: =IF($C4="","SIN PRECIO",$C4)
A5: VIGA 23-25CM | B5: METRO LINEAL | C5: 8500 | D5: SI | E5: =IF($C5="","SIN PRECIO",$C5)
A6: VIGA 25-30CM | B6: METRO LINEAL | C6: 9500 | D6: SI | E6: =IF($C6="","SIN PRECIO",$C6)
A7: MACHIMBRE 1/2 | B7: METRO 2 | C7: 8500 | D7: NO | E7: =IF($C7="","SIN PRECIO",$C7)
A8: MACHIMBRE 3/4 X4 1RA | B8: METRO 2 | C8: 9900 | D8: NO | E8: =IF($C8="","SIN PRECIO",$C8)
A9: MACHIMBRE 3/4 X5 1RA | B9: METRO 2 | C9: 10450 | D9: NO | E9: =IF($C9="","SIN PRECIO",$C9)
A10: MACHIMBRE 1"X6 | B10: METRO 2 | D10: NO | E10: =IF($C10="","SIN PRECIO",$C10)
A11: PUNTALES 7-10 | B11: UNIDAD | C11: 3500 | D11: NO | E11: =IF($C11="","SIN PRECIO",$C11)
A12: PUNTALES 10-12 | B12: UNIDAD | C12: 4500 | D12: NO | E12: =IF($C12="","SIN PRECIO",$C12)
A13: PUNTALES 13-15 | B13: UNIDAD | C13: 5500 | D13: NO | E13: =IF($C13="","SIN PRECIO",$C13)
A14: IMPREGNADOS 7-10 | B14: UNIDAD | C14: 6000 | D14: NO | E14: =IF($C14="","SIN PRECIO",$C14)
A15: IMPREGNADOS 10-12 | B15: UNIDAD | C15: 7000 | D15: NO | E15: =IF($C15="","SIN PRECIO",$C15)
A16: IMPREGNADOS 13-15 | B16: UNIDAD | C16: 8000 | D16: NO | E16: =IF($C16="","SIN PRECIO",$C16)
A17: ROLLIZOS IMPREGNADOS 13-15 | B17: METRO LINEAL | C17: 6500 | D17: SI | E17: =IF($C17="","SIN PRECIO",$C17)
A18: POSTES IMPREGNADO 16-18 | B18: METRO LINEAL | C18: 8500 | D18: SI | E18: =IF($C18="","SIN PRECIO",$C18)
A19: VIGAS IMPREGNADAS 20-22 | B19: METRO LINEAL | C19: 10000 | D19: SI | E19: =IF($C19="","SIN PRECIO",$C19)
A20: MEMBRANA 40KG | B20: UNIDAD | D20: NO | E20: =IF($C20="","SIN PRECIO",$C20)
A21: RUBEROID 20M | B21: UNIDAD | D21: NO | E21: =IF($C21="","SIN PRECIO",$C21)
A22: RUBEROID 40M | B22: UNIDAD | D22: NO | E22: =IF($C22="","SIN PRECIO",$C22)
A23: MEMBRANA EN PASTA 20 LTS | B23: UNIDAD | D23: NO | E23: =IF($C23="","SIN PRECIO",$C23)
A24: FENOLICOS 15MM INDUSTRIAL | B24: UNIDAD | D24: NO | E24: =IF($C24="","SIN PRECIO",$C24)
A25: FENOLICOS 16MM COMERCIAL | B25: UNIDAD | D25: NO | E25: =IF($C25="","SIN PRECIO",$C25)
A26: FENOLICOS 18MM INDUSTRIAL | B26: UNIDAD | C26: 30000 | D26: NO | E26: =IF($C26="","SIN PRECIO",$C26)
A27: FENOLICOS 18MM COMERCIAL | B27: UNIDAD | C27: 34000 | D27: NO | E27: =IF($C27="","SIN PRECIO",$C27)
A28: FENOLICOS 18MM 1 CARA BUENA | B28: UNIDAD | D28: NO | E28: =IF($C28="","SIN PRECIO",$C28)
A29: DECK PINO IMPREGNADO | B29: METRO 2 | C29: 28000 | D29: NO | E29: =IF($C29="","SIN PRECIO",$C29)
A30: TABLAS DE PINO CEP. 3/4X4 3,66 | B30: UNIDAD/M2 | D30: NO | E30: =IF($C30="","SIN PRECIO",$C30)
A31: TABLAS DE PINO S/C. 1 X 4 X 3,66 | B31: UNIDAD | C31: 4400 | D31: NO | E31: =IF($C31="","SIN PRECIO",$C31)
A32: TABLAS DE PINO S/C. 1 X 6 X 3,66 | B32: UNIDAD | C32: 6580 | D32: NO | E32: =IF($C32="","SIN PRECIO",$C32)
A33: ALFAJIAS 1/2X2 2,20 | B33: UNIDAD | C33: 770 | D33: NO | E33: =IF($C33="","SIN PRECIO",$C33)
A34: ALFAJIAS 2X1 2.20 | B34: UNIDAD | C34: 1550 | D34: NO | E34: =IF($C34="","SIN PRECIO",$C34)
A35: ALFAJIAS 1X4 2,20 | B35: UNIDAD | C35: 3100 | D35: NO | E35: =IF($C35="","SIN PRECIO",$C35)
A36: ALFAJIAS 1X6 2,20 | B36: UNIDAD | C36: 4600 | D36: NO | E36: =IF($C36="","SIN PRECIO",$C36)
A37: ALFAJIAS 1X8 2,20 | B37: UNIDAD | C37: 6100 | D37: NO | E37: =IF($C37="","SIN PRECIO",$C37)
A38: ALFAJIAS 2X2 2,20 | B38: UNIDAD | C38: 3100 | D38: NO | E38: =IF($C38="","SIN PRECIO",$C38)
A39: ALFAJIAS 2X4 2,20 | B39: UNIDAD | C39: 6150 | D39: NO | E39: =IF($C39="","SIN PRECIO",$C39)
A40: ALFAJIAS 3X3 2,20 | B40: UNIDAD | C40: 6900 | D40: NO | E40: =IF($C40="","SIN PRECIO",$C40)
...
